2025-03-17 22:55:50,295 INFO    MainThread:10112 [wandb_setup.py:_flush():79] Current SDK version is 0.18.7
2025-03-17 22:55:50,295 INFO    MainThread:10112 [wandb_setup.py:_flush():79] Configure stats pid to 10112
2025-03-17 22:55:50,296 INFO    MainThread:10112 [wandb_setup.py:_flush():79] Loading settings from C:\Users\admin.DESKTOP-7USASVH\.config\wandb\settings
2025-03-17 22:55:50,296 INFO    MainThread:10112 [wandb_setup.py:_flush():79] Loading settings from D:\Git\IDCDF-WKY\wandb\settings
2025-03-17 22:55:50,297 INFO    MainThread:10112 [wandb_setup.py:_flush():79] Loading settings from environment variables: {}
2025-03-17 22:55:50,297 INFO    MainThread:10112 [wandb_setup.py:_flush():79] Applying setup settings: {'mode': None, '_disable_service': None}
2025-03-17 22:55:50,297 INFO    MainThread:10112 [wandb_setup.py:_flush():79] Inferring run settings from compute environment: {'program_relpath': 'run.py', 'program_abspath': 'd:\\Git\\IDCDF-WKY\\run.py', 'program': 'd:\\Git\\IDCDF-WKY\\run.py'}
2025-03-17 22:55:50,297 INFO    MainThread:10112 [wandb_setup.py:_flush():79] Applying login settings: {}
2025-03-17 22:55:50,298 INFO    MainThread:10112 [wandb_init.py:_log_setup():533] Logging user logs to D:\Git\IDCDF-WKY\wandb\run-20250317_225550-bsavpq56\logs\debug.log
2025-03-17 22:55:50,298 INFO    MainThread:10112 [wandb_init.py:_log_setup():534] Logging internal logs to D:\Git\IDCDF-WKY\wandb\run-20250317_225550-bsavpq56\logs\debug-internal.log
2025-03-17 22:55:50,299 INFO    MainThread:10112 [wandb_init.py:init():619] calling init triggers
2025-03-17 22:55:50,299 INFO    MainThread:10112 [wandb_init.py:init():626] wandb.init called with sweep_config: {}
config: {'method': 'idcdm', 'epoch': 10, 'seed': 0, 'data_type': 'idcd', 'dtype': torch.float64, 'device': 'cpu', 'batch_size': 256, 'lr': 0.0007, 'test_size': 0.2, 'stu_latent_dim': 64, 'exer_latent_dim': 2, 'name': 'idcdm--seed0'}
2025-03-17 22:55:50,300 INFO    MainThread:10112 [wandb_init.py:init():669] starting backend
2025-03-17 22:55:50,300 INFO    MainThread:10112 [wandb_init.py:init():673] sending inform_init request
2025-03-17 22:55:50,300 INFO    MainThread:10112 [backend.py:_multiprocessing_setup():104] multiprocessing start_methods=spawn, using: spawn
2025-03-17 22:55:50,309 INFO    MainThread:10112 [wandb_init.py:init():686] backend started and connected
2025-03-17 22:55:50,328 INFO    MainThread:10112 [wandb_init.py:init():781] updated telemetry
2025-03-17 22:55:50,332 INFO    MainThread:10112 [wandb_init.py:init():814] communicating run to backend with 90.0 second timeout
2025-03-17 22:56:10,932 INFO    Thread-5 (wrapped_target):10112 [retry.py:__call__():172] Retry attempt failed:
Traceback (most recent call last):
  File "C:\Users\admin.DESKTOP-7USASVH\AppData\Local\Programs\Python\Python312\Lib\site-packages\urllib3\connection.py", line 196, in _new_conn
    sock = connection.create_connection(
           ^^^^^^^^^^^^^^^^^^^^^^^^^^^^^
  File "C:\Users\admin.DESKTOP-7USASVH\AppData\Local\Programs\Python\Python312\Lib\site-packages\urllib3\util\connection.py", line 60, in create_connection
    for res in socket.getaddrinfo(host, port, family, socket.SOCK_STREAM):
               ^^^^^^^^^^^^^^^^^^^^^^^^^^^^^^^^^^^^^^^^^^^^^^^^^^^^^^^^^^
  File "C:\Users\admin.DESKTOP-7USASVH\AppData\Local\Programs\Python\Python312\Lib\socket.py", line 964, in getaddrinfo
    for res in _socket.getaddrinfo(host, port, family, type, proto, flags):
               ^^^^^^^^^^^^^^^^^^^^^^^^^^^^^^^^^^^^^^^^^^^^^^^^^^^^^^^^^^^
socket.gaierror: [Errno 11001] getaddrinfo failed

The above exception was the direct cause of the following exception:

Traceback (most recent call last):
  File "C:\Users\admin.DESKTOP-7USASVH\AppData\Local\Programs\Python\Python312\Lib\site-packages\urllib3\connectionpool.py", line 789, in urlopen
    response = self._make_request(
               ^^^^^^^^^^^^^^^^^^^
  File "C:\Users\admin.DESKTOP-7USASVH\AppData\Local\Programs\Python\Python312\Lib\site-packages\urllib3\connectionpool.py", line 490, in _make_request
    raise new_e
  File "C:\Users\admin.DESKTOP-7USASVH\AppData\Local\Programs\Python\Python312\Lib\site-packages\urllib3\connectionpool.py", line 466, in _make_request
    self._validate_conn(conn)
  File "C:\Users\admin.DESKTOP-7USASVH\AppData\Local\Programs\Python\Python312\Lib\site-packages\urllib3\connectionpool.py", line 1095, in _validate_conn
    conn.connect()
  File "C:\Users\admin.DESKTOP-7USASVH\AppData\Local\Programs\Python\Python312\Lib\site-packages\urllib3\connection.py", line 615, in connect
    self.sock = sock = self._new_conn()
                       ^^^^^^^^^^^^^^^^
  File "C:\Users\admin.DESKTOP-7USASVH\AppData\Local\Programs\Python\Python312\Lib\site-packages\urllib3\connection.py", line 203, in _new_conn
    raise NameResolutionError(self.host, self, e) from e
urllib3.exceptions.NameResolutionError: <urllib3.connection.HTTPSConnection object at 0x0000020296895C70>: Failed to resolve 'api.wandb.ai' ([Errno 11001] getaddrinfo failed)

The above exception was the direct cause of the following exception:

Traceback (most recent call last):
  File "C:\Users\admin.DESKTOP-7USASVH\AppData\Local\Programs\Python\Python312\Lib\site-packages\requests\adapters.py", line 486, in send
    resp = conn.urlopen(
           ^^^^^^^^^^^^^
  File "C:\Users\admin.DESKTOP-7USASVH\AppData\Local\Programs\Python\Python312\Lib\site-packages\urllib3\connectionpool.py", line 843, in urlopen
    retries = retries.increment(
              ^^^^^^^^^^^^^^^^^^
  File "C:\Users\admin.DESKTOP-7USASVH\AppData\Local\Programs\Python\Python312\Lib\site-packages\urllib3\util\retry.py", line 519, in increment
    raise MaxRetryError(_pool, url, reason) from reason  # type: ignore[arg-type]
    ^^^^^^^^^^^^^^^^^^^^^^^^^^^^^^^^^^^^^^^^^^^^^^^^^^^
urllib3.exceptions.MaxRetryError: HTTPSConnectionPool(host='api.wandb.ai', port=443): Max retries exceeded with url: /graphql (Caused by NameResolutionError("<urllib3.connection.HTTPSConnection object at 0x0000020296895C70>: Failed to resolve 'api.wandb.ai' ([Errno 11001] getaddrinfo failed)"))

During handling of the above exception, another exception occurred:

Traceback (most recent call last):
  File "C:\Users\admin.DESKTOP-7USASVH\AppData\Local\Programs\Python\Python312\Lib\site-packages\wandb\sdk\lib\retry.py", line 131, in __call__
    result = self._call_fn(*args, **kwargs)
             ^^^^^^^^^^^^^^^^^^^^^^^^^^^^^^
  File "C:\Users\admin.DESKTOP-7USASVH\AppData\Local\Programs\Python\Python312\Lib\site-packages\wandb\sdk\internal\internal_api.py", line 400, in execute
    return self.client.execute(*args, **kwargs)  # type: ignore
           ^^^^^^^^^^^^^^^^^^^^^^^^^^^^^^^^^^^^
  File "C:\Users\admin.DESKTOP-7USASVH\AppData\Local\Programs\Python\Python312\Lib\site-packages\wandb\vendor\gql-0.2.0\wandb_gql\client.py", line 52, in execute
    result = self._get_result(document, *args, **kwargs)
             ^^^^^^^^^^^^^^^^^^^^^^^^^^^^^^^^^^^^^^^^^^^
  File "C:\Users\admin.DESKTOP-7USASVH\AppData\Local\Programs\Python\Python312\Lib\site-packages\wandb\vendor\gql-0.2.0\wandb_gql\client.py", line 60, in _get_result
    return self.transport.execute(document, *args, **kwargs)
           ^^^^^^^^^^^^^^^^^^^^^^^^^^^^^^^^^^^^^^^^^^^^^^^^^
  File "C:\Users\admin.DESKTOP-7USASVH\AppData\Local\Programs\Python\Python312\Lib\site-packages\wandb\sdk\lib\gql_request.py", line 58, in execute
    request = self.session.post(self.url, **post_args)
              ^^^^^^^^^^^^^^^^^^^^^^^^^^^^^^^^^^^^^^^^
  File "C:\Users\admin.DESKTOP-7USASVH\AppData\Local\Programs\Python\Python312\Lib\site-packages\requests\sessions.py", line 637, in post
    return self.request("POST", url, data=data, json=json, **kwargs)
           ^^^^^^^^^^^^^^^^^^^^^^^^^^^^^^^^^^^^^^^^^^^^^^^^^^^^^^^^^
  File "C:\Users\admin.DESKTOP-7USASVH\AppData\Local\Programs\Python\Python312\Lib\site-packages\requests\sessions.py", line 589, in request
    resp = self.send(prep, **send_kwargs)
           ^^^^^^^^^^^^^^^^^^^^^^^^^^^^^^
  File "C:\Users\admin.DESKTOP-7USASVH\AppData\Local\Programs\Python\Python312\Lib\site-packages\requests\sessions.py", line 703, in send
    r = adapter.send(request, **kwargs)
        ^^^^^^^^^^^^^^^^^^^^^^^^^^^^^^^
  File "C:\Users\admin.DESKTOP-7USASVH\AppData\Local\Programs\Python\Python312\Lib\site-packages\requests\adapters.py", line 519, in send
    raise ConnectionError(e, request=request)
requests.exceptions.ConnectionError: HTTPSConnectionPool(host='api.wandb.ai', port=443): Max retries exceeded with url: /graphql (Caused by NameResolutionError("<urllib3.connection.HTTPSConnection object at 0x0000020296895C70>: Failed to resolve 'api.wandb.ai' ([Errno 11001] getaddrinfo failed)"))
2025-03-17 22:57:21,320 ERROR   MainThread:10112 [wandb_init.py:init():841] encountered error: Run initialization has timed out after 90.0 sec. Please try increasing the timeout with the `init_timeout` setting: `wandb.init(settings=wandb.Settings(init_timeout=120))`.
2025-03-17 22:57:21,320 ERROR   MainThread:10112 [wandb_init.py:init():1266] error in wandb.init()
Traceback (most recent call last):
  File "C:\Users\admin.DESKTOP-7USASVH\AppData\Local\Programs\Python\Python312\Lib\site-packages\wandb\sdk\wandb_init.py", line 1256, in init
    return wi.init()
           ^^^^^^^^^
  File "C:\Users\admin.DESKTOP-7USASVH\AppData\Local\Programs\Python\Python312\Lib\site-packages\wandb\sdk\wandb_init.py", line 847, in init
    raise error
wandb.errors.errors.CommError: Run initialization has timed out after 90.0 sec. Please try increasing the timeout with the `init_timeout` setting: `wandb.init(settings=wandb.Settings(init_timeout=120))`.
2025-03-17 22:57:21,373 WARNING MsgRouterThr:10112 [router.py:message_loop():75] message_loop has been closed
