2025-03-18 20:50:54,548 INFO    MainThread:7308 [wandb_setup.py:_flush():79] Current SDK version is 0.18.7
2025-03-18 20:50:54,548 INFO    MainThread:7308 [wandb_setup.py:_flush():79] Configure stats pid to 7308
2025-03-18 20:50:54,548 INFO    MainThread:7308 [wandb_setup.py:_flush():79] Loading settings from C:\Users\admin.DESKTOP-7USASVH\.config\wandb\settings
2025-03-18 20:50:54,548 INFO    MainThread:7308 [wandb_setup.py:_flush():79] Loading settings from D:\Git\IDCDF-WKY\wandb\settings
2025-03-18 20:50:54,549 INFO    MainThread:7308 [wandb_setup.py:_flush():79] Loading settings from environment variables: {}
2025-03-18 20:50:54,549 INFO    MainThread:7308 [wandb_setup.py:_flush():79] Applying setup settings: {'mode': None, '_disable_service': None}
2025-03-18 20:50:54,549 INFO    MainThread:7308 [wandb_setup.py:_flush():79] Inferring run settings from compute environment: {'program_relpath': 'run.py', 'program_abspath': 'd:\\Git\\IDCDF-WKY\\run.py', 'program': 'd:\\Git\\IDCDF-WKY\\run.py'}
2025-03-18 20:50:54,551 INFO    MainThread:7308 [wandb_setup.py:_flush():79] Applying login settings: {}
2025-03-18 20:50:54,551 INFO    MainThread:7308 [wandb_init.py:_log_setup():533] Logging user logs to D:\Git\IDCDF-WKY\wandb\run-20250318_205054-5twj4378\logs\debug.log
2025-03-18 20:50:54,552 INFO    MainThread:7308 [wandb_init.py:_log_setup():534] Logging internal logs to D:\Git\IDCDF-WKY\wandb\run-20250318_205054-5twj4378\logs\debug-internal.log
2025-03-18 20:50:54,553 INFO    MainThread:7308 [wandb_init.py:init():619] calling init triggers
2025-03-18 20:50:54,555 INFO    MainThread:7308 [wandb_init.py:init():626] wandb.init called with sweep_config: {}
config: {'method': 'idcdm', 'epoch': 10, 'seed': 0, 'data_type': 'idcd', 'dtype': torch.float64, 'device': 'cpu', 'batch_size': 256, 'lr': 0.0007, 'test_size': 0.2, 'stu_latent_dim': 32, 'exer_latent_dim': 32, 'name': 'idcdm--seed0'}
2025-03-18 20:50:54,555 INFO    MainThread:7308 [wandb_init.py:init():669] starting backend
2025-03-18 20:50:54,555 INFO    MainThread:7308 [wandb_init.py:init():673] sending inform_init request
2025-03-18 20:50:54,560 INFO    MainThread:7308 [backend.py:_multiprocessing_setup():104] multiprocessing start_methods=spawn, using: spawn
2025-03-18 20:50:54,562 INFO    MainThread:7308 [wandb_init.py:init():686] backend started and connected
2025-03-18 20:50:54,593 INFO    MainThread:7308 [wandb_init.py:init():781] updated telemetry
2025-03-18 20:50:54,716 INFO    MainThread:7308 [wandb_init.py:init():814] communicating run to backend with 90.0 second timeout
2025-03-18 20:50:55,493 INFO    Thread-9 (wrapped_target):7308 [retry.py:__call__():172] Retry attempt failed:
Traceback (most recent call last):
  File "C:\Users\admin.DESKTOP-7USASVH\AppData\Local\Programs\Python\Python312\Lib\site-packages\urllib3\connectionpool.py", line 775, in urlopen
    self._prepare_proxy(conn)
  File "C:\Users\admin.DESKTOP-7USASVH\AppData\Local\Programs\Python\Python312\Lib\site-packages\urllib3\connectionpool.py", line 1044, in _prepare_proxy
    conn.connect()
  File "C:\Users\admin.DESKTOP-7USASVH\AppData\Local\Programs\Python\Python312\Lib\site-packages\urllib3\connection.py", line 652, in connect
    sock_and_verified = _ssl_wrap_socket_and_match_hostname(
                        ^^^^^^^^^^^^^^^^^^^^^^^^^^^^^^^^^^^^
  File "C:\Users\admin.DESKTOP-7USASVH\AppData\Local\Programs\Python\Python312\Lib\site-packages\urllib3\connection.py", line 805, in _ssl_wrap_socket_and_match_hostname
    ssl_sock = ssl_wrap_socket(
               ^^^^^^^^^^^^^^^^
  File "C:\Users\admin.DESKTOP-7USASVH\AppData\Local\Programs\Python\Python312\Lib\site-packages\urllib3\util\ssl_.py", line 465, in ssl_wrap_socket
    ssl_sock = _ssl_wrap_socket_impl(sock, context, tls_in_tls, server_hostname)
               ^^^^^^^^^^^^^^^^^^^^^^^^^^^^^^^^^^^^^^^^^^^^^^^^^^^^^^^^^^^^^^^^^
  File "C:\Users\admin.DESKTOP-7USASVH\AppData\Local\Programs\Python\Python312\Lib\site-packages\urllib3\util\ssl_.py", line 509, in _ssl_wrap_socket_impl
    return ssl_context.wrap_socket(sock, server_hostname=server_hostname)
           ^^^^^^^^^^^^^^^^^^^^^^^^^^^^^^^^^^^^^^^^^^^^^^^^^^^^^^^^^^^^^^
  File "C:\Users\admin.DESKTOP-7USASVH\AppData\Local\Programs\Python\Python312\Lib\ssl.py", line 455, in wrap_socket
    return self.sslsocket_class._create(
           ^^^^^^^^^^^^^^^^^^^^^^^^^^^^^
  File "C:\Users\admin.DESKTOP-7USASVH\AppData\Local\Programs\Python\Python312\Lib\ssl.py", line 1042, in _create
    self.do_handshake()
  File "C:\Users\admin.DESKTOP-7USASVH\AppData\Local\Programs\Python\Python312\Lib\ssl.py", line 1320, in do_handshake
    self._sslobj.do_handshake()
ConnectionAbortedError: [WinError 10053] 你的主机中的软件中止了一个已建立的连接。

During handling of the above exception, another exception occurred:

Traceback (most recent call last):
  File "C:\Users\admin.DESKTOP-7USASVH\AppData\Local\Programs\Python\Python312\Lib\site-packages\requests\adapters.py", line 486, in send
    resp = conn.urlopen(
           ^^^^^^^^^^^^^
  File "C:\Users\admin.DESKTOP-7USASVH\AppData\Local\Programs\Python\Python312\Lib\site-packages\urllib3\connectionpool.py", line 843, in urlopen
    retries = retries.increment(
              ^^^^^^^^^^^^^^^^^^
  File "C:\Users\admin.DESKTOP-7USASVH\AppData\Local\Programs\Python\Python312\Lib\site-packages\urllib3\util\retry.py", line 474, in increment
    raise reraise(type(error), error, _stacktrace)
          ^^^^^^^^^^^^^^^^^^^^^^^^^^^^^^^^^^^^^^^^
  File "C:\Users\admin.DESKTOP-7USASVH\AppData\Local\Programs\Python\Python312\Lib\site-packages\urllib3\util\util.py", line 38, in reraise
    raise value.with_traceback(tb)
  File "C:\Users\admin.DESKTOP-7USASVH\AppData\Local\Programs\Python\Python312\Lib\site-packages\urllib3\connectionpool.py", line 775, in urlopen
    self._prepare_proxy(conn)
  File "C:\Users\admin.DESKTOP-7USASVH\AppData\Local\Programs\Python\Python312\Lib\site-packages\urllib3\connectionpool.py", line 1044, in _prepare_proxy
    conn.connect()
  File "C:\Users\admin.DESKTOP-7USASVH\AppData\Local\Programs\Python\Python312\Lib\site-packages\urllib3\connection.py", line 652, in connect
    sock_and_verified = _ssl_wrap_socket_and_match_hostname(
                        ^^^^^^^^^^^^^^^^^^^^^^^^^^^^^^^^^^^^
  File "C:\Users\admin.DESKTOP-7USASVH\AppData\Local\Programs\Python\Python312\Lib\site-packages\urllib3\connection.py", line 805, in _ssl_wrap_socket_and_match_hostname
    ssl_sock = ssl_wrap_socket(
               ^^^^^^^^^^^^^^^^
  File "C:\Users\admin.DESKTOP-7USASVH\AppData\Local\Programs\Python\Python312\Lib\site-packages\urllib3\util\ssl_.py", line 465, in ssl_wrap_socket
    ssl_sock = _ssl_wrap_socket_impl(sock, context, tls_in_tls, server_hostname)
               ^^^^^^^^^^^^^^^^^^^^^^^^^^^^^^^^^^^^^^^^^^^^^^^^^^^^^^^^^^^^^^^^^
  File "C:\Users\admin.DESKTOP-7USASVH\AppData\Local\Programs\Python\Python312\Lib\site-packages\urllib3\util\ssl_.py", line 509, in _ssl_wrap_socket_impl
    return ssl_context.wrap_socket(sock, server_hostname=server_hostname)
           ^^^^^^^^^^^^^^^^^^^^^^^^^^^^^^^^^^^^^^^^^^^^^^^^^^^^^^^^^^^^^^
  File "C:\Users\admin.DESKTOP-7USASVH\AppData\Local\Programs\Python\Python312\Lib\ssl.py", line 455, in wrap_socket
    return self.sslsocket_class._create(
           ^^^^^^^^^^^^^^^^^^^^^^^^^^^^^
  File "C:\Users\admin.DESKTOP-7USASVH\AppData\Local\Programs\Python\Python312\Lib\ssl.py", line 1042, in _create
    self.do_handshake()
  File "C:\Users\admin.DESKTOP-7USASVH\AppData\Local\Programs\Python\Python312\Lib\ssl.py", line 1320, in do_handshake
    self._sslobj.do_handshake()
urllib3.exceptions.ProtocolError: ('Connection aborted.', ConnectionAbortedError(10053, '你的主机中的软件中止了一个已建立的连接。', None, 10053, None))

During handling of the above exception, another exception occurred:

Traceback (most recent call last):
  File "C:\Users\admin.DESKTOP-7USASVH\AppData\Local\Programs\Python\Python312\Lib\site-packages\wandb\sdk\lib\retry.py", line 131, in __call__
    result = self._call_fn(*args, **kwargs)
             ^^^^^^^^^^^^^^^^^^^^^^^^^^^^^^
  File "C:\Users\admin.DESKTOP-7USASVH\AppData\Local\Programs\Python\Python312\Lib\site-packages\wandb\sdk\internal\internal_api.py", line 400, in execute
    return self.client.execute(*args, **kwargs)  # type: ignore
           ^^^^^^^^^^^^^^^^^^^^^^^^^^^^^^^^^^^^
  File "C:\Users\admin.DESKTOP-7USASVH\AppData\Local\Programs\Python\Python312\Lib\site-packages\wandb\vendor\gql-0.2.0\wandb_gql\client.py", line 52, in execute
    result = self._get_result(document, *args, **kwargs)
             ^^^^^^^^^^^^^^^^^^^^^^^^^^^^^^^^^^^^^^^^^^^
  File "C:\Users\admin.DESKTOP-7USASVH\AppData\Local\Programs\Python\Python312\Lib\site-packages\wandb\vendor\gql-0.2.0\wandb_gql\client.py", line 60, in _get_result
    return self.transport.execute(document, *args, **kwargs)
           ^^^^^^^^^^^^^^^^^^^^^^^^^^^^^^^^^^^^^^^^^^^^^^^^^
  File "C:\Users\admin.DESKTOP-7USASVH\AppData\Local\Programs\Python\Python312\Lib\site-packages\wandb\sdk\lib\gql_request.py", line 58, in execute
    request = self.session.post(self.url, **post_args)
              ^^^^^^^^^^^^^^^^^^^^^^^^^^^^^^^^^^^^^^^^
  File "C:\Users\admin.DESKTOP-7USASVH\AppData\Local\Programs\Python\Python312\Lib\site-packages\requests\sessions.py", line 637, in post
    return self.request("POST", url, data=data, json=json, **kwargs)
           ^^^^^^^^^^^^^^^^^^^^^^^^^^^^^^^^^^^^^^^^^^^^^^^^^^^^^^^^^
  File "C:\Users\admin.DESKTOP-7USASVH\AppData\Local\Programs\Python\Python312\Lib\site-packages\requests\sessions.py", line 589, in request
    resp = self.send(prep, **send_kwargs)
           ^^^^^^^^^^^^^^^^^^^^^^^^^^^^^^
  File "C:\Users\admin.DESKTOP-7USASVH\AppData\Local\Programs\Python\Python312\Lib\site-packages\requests\sessions.py", line 703, in send
    r = adapter.send(request, **kwargs)
        ^^^^^^^^^^^^^^^^^^^^^^^^^^^^^^^
  File "C:\Users\admin.DESKTOP-7USASVH\AppData\Local\Programs\Python\Python312\Lib\site-packages\requests\adapters.py", line 501, in send
    raise ConnectionError(err, request=request)
requests.exceptions.ConnectionError: ('Connection aborted.', ConnectionAbortedError(10053, '你的主机中的软件中止了一个已建立的连接。', None, 10053, None))
2025-03-18 20:52:03,867 INFO    MainThread:7308 [wandb_init.py:init():867] starting run threads in backend
2025-03-18 20:52:04,294 INFO    MainThread:7308 [wandb_run.py:_console_start():2456] atexit reg
2025-03-18 20:52:04,294 INFO    MainThread:7308 [wandb_run.py:_redirect():2305] redirect: wrap_raw
2025-03-18 20:52:04,295 INFO    MainThread:7308 [wandb_run.py:_redirect():2370] Wrapping output streams.
2025-03-18 20:52:04,295 INFO    MainThread:7308 [wandb_run.py:_redirect():2395] Redirects installed.
2025-03-18 20:52:04,302 INFO    MainThread:7308 [wandb_init.py:init():911] run started, returning control to user process
2025-03-18 20:56:25,906 WARNING MsgRouterThr:7308 [router.py:message_loop():75] message_loop has been closed
